Workbook

Sheet Revision
A1: Revision | B1: Description
A2: 1 | B2: 최초 작성
A3: 2 | B3: 실제 자부담비용 입력란 추가. 실제 자부담비용 입력 후 추가분/부족분 계산하여 정산 이상 유무 메시지 출력. 인당 최소 자부담 비용 필드 추가. 구간 정산 메시지 명확화 (변경 전: 60,000원 초과 금액에 대해 40% 자체 부담 → 변경 후: '나' 구간 자부담 비용 + 60,000원 초과 금액에 대해 40% 자체 부담)
A4: 3 | B4: 상품비 사용 기준 변경(20명 이상 → 10명 이상)에 따른 수식 변경
A5: 4 | B5: 참석자 이름을 입력하면 사번이 자동으로 입력되도록 수정. 동일한 이름이 여러명일 경우 '사번확인요' 메시지가 출력되고, 사번 셀의 색상이 노란색으로 변경됨. 사번이 다를 경우 수기로 입력하면 메시지 및 노란색 사라지도록 함.

Sheet 비용내역
D2: 연노랑색 셀에만 입력
B4: 번호 | C4: 사번 | D4: 정회원 참석자 | F4: 내역 | G4: 비용 | H4: 구분 | J4: 참석자 수 (A) | K4: =COUNTA(D5:D124) -> 0
B5: 1 | C5: =IF(D5="","",_xlfn.XLOOKUP(D5,'Global ID'!$C$1:$C$2000,'Global ID'!$B$1:$B$2000,,0)) | E5: =IF(NOT(_xlfn.ISFORMULA(C5)),"",IF(D5="","",IF(COUNTIF('Global ID'!$C$1:$C$2000,D5)>1,"사번확인요","")))
B6: 2 | C6: =IF(D6="","",_xlfn.XLOOKUP(D6,'Global ID'!$C$1:$C$2000,'Global ID'!$B$1:$B$2000,,0)) | E6: =IF(NOT(_xlfn.ISFORMULA(C6)),"",IF(D6="","",IF(COUNTIF('Global ID'!$C:$C,D6)>1,"사번확인요",""))) | J6: 총 비용 (B) | K6: =SUM(G5:G25) -> 0
B7: 3 | C7: =IF(D7="","",_xlfn.XLOOKUP(D7,'Global ID'!$C$1:$C$2000,'Global ID'!$B$1:$B$2000,,0)) | E7: =IF(NOT(_xlfn.ISFORMULA(C7)),"",IF(D7="","",IF(COUNTIF('Global ID'!$C:$C,D7)>1,"사번확인요",""))) | J7: 행사비 (C) | K7: =SUMIF($H$5:$H$25,"행사비",$G$5:$G$25) -> 0
B8: 4 | C8: =IF(D8="","",_xlfn.XLOOKUP(D8,'Global ID'!$C$1:$C$2000,'Global ID'!$B$1:$B$2000,,0)) | E8: =IF(NOT(_xlfn.ISFORMULA(C8)),"",IF(D8="","",IF(COUNTIF('Global ID'!$C:$C,D8)>1,"사번확인요",""))) | J8: 시설 및 장비 이용료 (D) | K8: =SUMIF($H$5:$H$25,"시설 및 장비 이용료",$G$5:$G$25) -> 0
B9: 5 | C9: =IF(D9="","",_xlfn.XLOOKUP(D9,'Global ID'!$C$1:$C$2000,'Global ID'!$B$1:$B$2000,,0)) | E9: =IF(NOT(_xlfn.ISFORMULA(C9)),"",IF(D9="","",IF(COUNTIF('Global ID'!$C:$C,D9)>1,"사번확인요",""))) | J9: 상품(E) | K9: =SUMIF($H$5:$H$25,"상품",$G$5:$G$25) -> 0 | L9: =IF(K9=0,"",IF(K4<10,"필요 참석자 수 부족. 최소 정회원 10명 이상 참석 시 상품비 사용 가능. 상품비 "&TEXT(K9,"0,0")&"원 전액 행사비에 포함 후 정산",IF((K9+SUM(G30:G34))>500000,"상품비 연 50만원 초과 불가. 총 상품비용 "&TEXT(K9+SUM(G30:G34),"0,0")&"으로, 초과 금액 "&TEXT((K9+SUM(G30:G34))-500000,"0,0")&"원은 행사비에 포함 후 정산","")))
B10: 6 | C10: =IF(D10="","",_xlfn.XLOOKUP(D10,'Global ID'!$C$1:$C$2000,'Global ID'!$B$1:$B$2000,,0)) | E10: =IF(NOT(_xlfn.ISFORMULA(C10)),"",IF(D10="","",IF(COUNTIF('Global ID'!$C:$C,D10)>1,"사번확인요",""))) | J10: ="※ 본 행사 상품비 잔여 한도: "&TEXT(500000-SUM(G30:G34),"0,0")&"원" -> ※ 본 행사 상품비 잔여 한도: 500,000원
B11: 7 | C11: =IF(D11="","",_xlfn.XLOOKUP(D11,'Global ID'!$C$1:$C$2000,'Global ID'!$B$1:$B$2000,,0)) | E11: =IF(NOT(_xlfn.ISFORMULA(C11)),"",IF(D11="","",IF(COUNTIF('Global ID'!$C:$C,D11)>1,"사번확인요","")))
B12: 8 | C12: =IF(D12="","",_xlfn.XLOOKUP(D12,'Global ID'!$C$1:$C$2000,'Global ID'!$B$1:$B$2000,,0)) | E12: =IF(NOT(_xlfn.ISFORMULA(C12)),"",IF(D12="","",IF(COUNTIF('Global ID'!$C:$C,D12)>1,"사번확인요",""))) | J12: 인당 행사비 (F)=(C)/(A) | K12: {=IF(K4=0,"",_xlfn.IFS(K4<10,(K7+K9)/K4,K9+SUM(G30:G34)>500000,(K7+(K9+SUM(G30:G34)-500000))/K4,AND(K4>=10,K9+SUM(G30:G34)<=500000),K7/K4))} | L12: {=IF(K7=0,"",_xlfn.IFS($K$12="","",$K$12<=30000, "전액지원", $K$12<=60000, "20% 자체 부담", $K$12<=120000, "'나' 구간 자부담 비용 + 60,000원 초과 금액에 대해 40% 자체 부담", $K$12>120000, "85,000원 이외 금액 자체 부담(최대 인당 8.5만원 지원)"))}
B13: 9 | C13: =IF(D13="","",_xlfn.XLOOKUP(D13,'Global ID'!$C$1:$C$2000,'Global ID'!$B$1:$B$2000,,0)) | E13: =IF(NOT(_xlfn.ISFORMULA(C13)),"",IF(D13="","",IF(COUNTIF('Global ID'!$C:$C,D13)>1,"사번확인요","")))
B14: 10 | C14: =IF(D14="","",_xlfn.XLOOKUP(D14,'Global ID'!$C$1:$C$2000,'Global ID'!$B$1:$B$2000,,0)) | E14: =IF(NOT(_xlfn.ISFORMULA(C14)),"",IF(D14="","",IF(COUNTIF('Global ID'!$C:$C,D14)>1,"사번확인요",""))) | J14: 정산 구간 | K14: 인당 구간 비용 | L14: 인당 자부담 비용
B15: 11 | C15: =IF(D15="","",_xlfn.XLOOKUP(D15,'Global ID'!$C$1:$C$2000,'Global ID'!$B$1:$B$2000,,0)) | E15: =IF(NOT(_xlfn.ISFORMULA(C15)),"",IF(D15="","",IF(COUNTIF('Global ID'!$C:$C,D15)>1,"사번확인요",""))) | J15: 가. (F) ≤ 30,000원 | K15: {=_xlfn.IFS(K12<=30000,K12,K12>30000,0)} -> 0 | L15: =K15*0 -> 0
B16: 12 | C16: =IF(D16="","",_xlfn.XLOOKUP(D16,'Global ID'!$C$1:$C$2000,'Global ID'!$B$1:$B$2000,,0)) | E16: =IF(NOT(_xlfn.ISFORMULA(C16)),"",IF(D16="","",IF(COUNTIF('Global ID'!$C:$C,D16)>1,"사번확인요",""))) | J16: 나. 30,000원 ＜ (F) ≤ 60,000원 | K16: {=_xlfn.IFS(OR(K12<=30000,K12>120000),0,AND(K12>30000,K12<=60000),K12,K12>60000,60000)} -> 0 | L16: =K16*20% -> 0
B17: 13 | C17: =IF(D17="","",_xlfn.XLOOKUP(D17,'Global ID'!$C$1:$C$2000,'Global ID'!$B$1:$B$2000,,0)) | E17: =IF(NOT(_xlfn.ISFORMULA(C17)),"",IF(D17="","",IF(COUNTIF('Global ID'!$C:$C,D17)>1,"사번확인요",""))) | J17: 다. 60,000원 ＜ (F) ≤ 120,000원 | K17: {=_xlfn.IFS(OR(K12<=60000,K12>120000),0,AND(K12>60000,K12<=120000),K12-60000,K12>120000,60000)} -> 0 | L17: =K17*40% -> 0
B18: 14 | C18: =IF(D18="","",_xlfn.XLOOKUP(D18,'Global ID'!$C$1:$C$2000,'Global ID'!$B$1:$B$2000,,0)) | E18: =IF(NOT(_xlfn.ISFORMULA(C18)),"",IF(D18="","",IF(COUNTIF('Global ID'!$C:$C,D18)>1,"사번확인요",""))) | J18: 라. 120,000원 ＜ (F) | K18: {=_xlfn.IFS(K12<=120000,0,K12>120000,K12)} | L18: =IF(ISERROR(IF(K18=0,0,K18-85000)),"",IF(K18=0,0,K18-85000))
B19: 15 | C19: =IF(D19="","",_xlfn.XLOOKUP(D19,'Global ID'!$C$1:$C$2000,'Global ID'!$B$1:$B$2000,,0)) | E19: =IF(NOT(_xlfn.ISFORMULA(C19)),"",IF(D19="","",IF(COUNTIF('Global ID'!$C:$C,D19)>1,"사번확인요","")))
B20: 16 | C20: =IF(D20="","",_xlfn.XLOOKUP(D20,'Global ID'!$C$1:$C$2000,'Global ID'!$B$1:$B$2000,,0)) | E20: =IF(NOT(_xlfn.ISFORMULA(C20)),"",IF(D20="","",IF(COUNTIF('Global ID'!$C:$C,D20)>1,"사번확인요",""))) | J20: 인당 최소 자부담 비용 | K20: =SUM(L15:L18) -> 0
B21: 17 | C21: =IF(D21="","",_xlfn.XLOOKUP(D21,'Global ID'!$C$1:$C$2000,'Global ID'!$B$1:$B$2000,,0)) | E21: =IF(NOT(_xlfn.ISFORMULA(C21)),"",IF(D21="","",IF(COUNTIF('Global ID'!$C:$C,D21)>1,"사번확인요",""))) | J21: 총 최소 자부담 비용 | K21: =SUM(L15:L18)*K4 -> 0
B22: 18 | C22: =IF(D22="","",_xlfn.XLOOKUP(D22,'Global ID'!$C$1:$C$2000,'Global ID'!$B$1:$B$2000,,0)) | E22: =IF(NOT(_xlfn.ISFORMULA(C22)),"",IF(D22="","",IF(COUNTIF('Global ID'!$C:$C,D22)>1,"사번확인요",""))) | J22: 총 최소 자부담 비율 | K22: =IF(ISERROR(K21/K6),"",K21/K6)
B23: 19 | C23: =IF(D23="","",_xlfn.XLOOKUP(D23,'Global ID'!$C$1:$C$2000,'Global ID'!$B$1:$B$2000,,0)) | E23: =IF(NOT(_xlfn.ISFORMULA(C23)),"",IF(D23="","",IF(COUNTIF('Global ID'!$C:$C,D23)>1,"사번확인요","")))
B24: 20 | C24: =IF(D24="","",_xlfn.XLOOKUP(D24,'Global ID'!$C$1:$C$2000,'Global ID'!$B$1:$B$2000,,0)) | E24: =IF(NOT(_xlfn.ISFORMULA(C24)),"",IF(D24="","",IF(COUNTIF('Global ID'!$C:$C,D24)>1,"사번확인요",""))) | J24: 실제 자부담 비용
B25: 21 | C25: =IF(D25="","",_xlfn.XLOOKUP(D25,'Global ID'!$C$1:$C$2000,'Global ID'!$B$1:$B$2000,,0)) | E25: =IF(NOT(_xlfn.ISFORMULA(C25)),"",IF(D25="","",IF(COUNTIF('Global ID'!$C:$C,D25)>1,"사번확인요",""))) | J25: 실제 자부담 비율 | K25: =IF(K24="","",K24/K6) | L25: =IF(K25="","",IF(K25>=K22,"정산 문제 없음. 최소 자부담 비용보다 "&TEXT(K24-K21,"#,#")&"원 추가 부담함", "최소 자부담 비용 미달. "&TEXT(K21-K24,"#,#")&"원 추가 자부담 필요."))
B26: 22 | C26: =IF(D26="","",_xlfn.XLOOKUP(D26,'Global ID'!$C$1:$C$2000,'Global ID'!$B$1:$B$2000,,0)) | E26: =IF(NOT(_xlfn.ISFORMULA(C26)),"",IF(D26="","",IF(COUNTIF('Global ID'!$C:$C,D26)>1,"사번확인요","")))
B27: 23 | C27: =IF(D27="","",_xlfn.XLOOKUP(D27,'Global ID'!$C$1:$C$2000,'Global ID'!$B$1:$B$2000,,0)) | E27: =IF(NOT(_xlfn.ISFORMULA(C27)),"",IF(D27="","",IF(COUNTIF('Global ID'!$C:$C,D27)>1,"사번확인요",""))) | F27: !! 당해 년도 상품비 사용 이력이 있을 경우 반드시 입력 !!
B28: 24 | C28: =IF(D28="","",_xlfn.XLOOKUP(D28,'Global ID'!$C$1:$C$2000,'Global ID'!$B$1:$B$2000,,0)) | E28: =IF(NOT(_xlfn.ISFORMULA(C28)),"",IF(D28="","",IF(COUNTIF('Global ID'!$C:$C,D28)>1,"사번확인요",""))) | F28: 상품비 사용 이력
B29: 25 | C29: =IF(D29="","",_xlfn.XLOOKUP(D29,'Global ID'!$C$1:$C$2000,'Global ID'!$B$1:$B$2000,,0)) | E29: =IF(NOT(_xlfn.ISFORMULA(C29)),"",IF(D29="","",IF(COUNTIF('Global ID'!$C:$C,D29)>1,"사번확인요",""))) | F29: 날짜 | G29: 사용금액
B30: 26 | C30: =IF(D30="","",_xlfn.XLOOKUP(D30,'Global ID'!$C$1:$C$2000,'Global ID'!$B$1:$B$2000,,0)) | E30: =IF(NOT(_xlfn.ISFORMULA(C30)),"",IF(D30="","",IF(COUNTIF('Global ID'!$C:$C,D30)>1,"사번확인요",""))) | J30: 총 회사 지원금 | K30: =K6-K24 -> 0
B31: 27 | C31: =IF(D31="","",_xlfn.XLOOKUP(D31,'Global ID'!$C$1:$C$2000,'Global ID'!$B$1:$B$2000,,0)) | E31: =IF(NOT(_xlfn.ISFORMULA(C31)),"",IF(D31="","",IF(COUNTIF('Global ID'!$C:$C,D31)>1,"사번확인요","")))
B32: 28 | C32: =IF(D32="","",_xlfn.XLOOKUP(D32,'Global ID'!$C$1:$C$2000,'Global ID'!$B$1:$B$2000,,0)) | E32: =IF(NOT(_xlfn.ISFORMULA(C32)),"",IF(D32="","",IF(COUNTIF('Global ID'!$C:$C,D32)>1,"사번확인요","")))
B33: 29 | C33: =IF(D33="","",_xlfn.XLOOKUP(D33,'Global ID'!$C$1:$C$2000,'Global ID'!$B$1:$B$2000,,0)) | E33: =IF(NOT(_xlfn.ISFORMULA(C33)),"",IF(D33="","",IF(COUNTIF('Global ID'!$C:$C,D33)>1,"사번확인요","")))
B34: 30 | C34: =IF(D34="","",_xlfn.XLOOKUP(D34,'Global ID'!$C$1:$C$2000,'Global ID'!$B$1:$B$2000,,0)) | E34: =IF(NOT(_xlfn.ISFORMULA(C34)),"",IF(D34="","",IF(COUNTIF('Global ID'!$C:$C,D34)>1,"사번확인요","")))
B35: 31 | C35: =IF(D35="","",_xlfn.XLOOKUP(D35,'Global ID'!$C$1:$C$2000,'Global ID'!$B$1:$B$2000,,0)) | E35: =IF(NOT(_xlfn.ISFORMULA(C35)),"",IF(D35="","",IF(COUNTIF('Global ID'!$C:$C,D35)>1,"사번확인요","")))
B36: 32 | C36: =IF(D36="","",_xlfn.XLOOKUP(D36,'Global ID'!$C$1:$C$2000,'Global ID'!$B$1:$B$2000,,0)) | E36: =IF(NOT(_xlfn.ISFORMULA(C36)),"",IF(D36="","",IF(COUNTIF('Global ID'!$C:$C,D36)>1,"사번확인요","")))
B37: 33 | C37: =IF(D37="","",_xlfn.XLOOKUP(D37,'Global ID'!$C$1:$C$2000,'Global ID'!$B$1:$B$2000,,0)) | E37: =IF(NOT(_xlfn.ISFORMULA(C37)),"",IF(D37="","",IF(COUNTIF('Global ID'!$C:$C,D37)>1,"사번확인요","")))
B38: 34 | C38: =IF(D38="","",_xlfn.XLOOKUP(D38,'Global ID'!$C$1:$C$2000,'Global ID'!$B$1:$B$2000,,0)) | E38: =IF(NOT(_xlfn.ISFORMULA(C38)),"",IF(D38="","",IF(COUNTIF('Global ID'!$C:$C,D38)>1,"사번확인요","")))
B39: 35 | C39: =IF(D39="","",_xlfn.XLOOKUP(D39,'Global ID'!$C$1:$C$2000,'Global ID'!$B$1:$B$2000,,0)) | E39: =IF(NOT(_xlfn.ISFORMULA(C39)),"",IF(D39="","",IF(COUNTIF('Global ID'!$C:$C,D39)>1,"사번확인요","")))
B40: 36 | C40: =IF(D40="","",_xlfn.XLOOKUP(D40,'Global ID'!$C$1:$C$2000,'Global ID'!$B$1:$B$2000,,0)) | E40: =IF(NOT(_xlfn.ISFORMULA(C40)),"",IF(D40="","",IF(COUNTIF('Global ID'!$C:$C,D40)>1,"사번확인요","")))
B41: 37 | C41: =IF(D41="","",_xlfn.XLOOKUP(D41,'Global ID'!$C$1:$C$2000,'Global ID'!$B$1:$B$2000,,0)) | E41: =IF(NOT(_xlfn.ISFORMULA(C41)),"",IF(D41="","",IF(COUNTIF('Global ID'!$C:$C,D41)>1,"사번확인요","")))
B42: 38 | C42: =IF(D42="","",_xlfn.XLOOKUP(D42,'Global ID'!$C$1:$C$2000,'Global ID'!$B$1:$B$2000,,0)) | E42: =IF(NOT(_xlfn.ISFORMULA(C42)),"",IF(D42="","",IF(COUNTIF('Global ID'!$C:$C,D42)>1,"사번확인요","")))
...

Sheet 행사사진
A1: ※ 이 곳에 인원수를 확인할 수 있는 단체 사진을 첨부해 주세요

Sheet 영수증
A1: ※ 이 곳에 행사에 사용한 비용의 영수증을 첨부해 주세요
B4: <법인카드 영수증 - 지원금> | D4: <개인카드 영수증 - 자부담>

Sheet Global ID
A1: Global ID | B1: EMP ID | C1: `
A2: CG000424 | B2: 424 | C2: 유충열 | D2: =TEXT(A2,"00000000") -> CG000424
A3: CG000484 | B3: 484 | C3: 김옥진 | D3: =TEXT(A3,"00000000") -> CG000484
A4: CG000567 | B4: 567 | C4: 조규석 | D4: =TEXT(A4,"00000000") -> CG000567
A5: CG000611 | B5: 611 | C5: 이해표 | D5: =TEXT(A5,"00000000") -> CG000611
A6: CG000616 | B6: 616 | C6: 이재욱 | D6: =TEXT(A6,"00000000") -> CG000616
A7: CG000635 | B7: 635 | C7: 정익순 | D7: =TEXT(A7,"00000000") -> CG000635
A8: CG000664 | B8: 664 | C8: 최영민 | D8: =TEXT(A8,"00000000") -> CG000664
A9: CG000699 | B9: 699 | C9: 오춘석 | D9: =TEXT(A9,"00000000") -> CG000699
A10: CG000714 | B10: 714 | C10: 유영종 | D10: =TEXT(A10,"00000000") -> CG000714
A11: CG000715 | B11: 715 | C11: 조천석 | D11: =TEXT(A11,"00000000") -> CG000715
A12: CG000743 | B12: 743 | C12: 김애란 | D12: =TEXT(A12,"00000000") -> CG000743
A13: CG000766 | B13: 766 | C13: 이은기 | D13: =TEXT(A13,"00000000") -> CG000766
... A1316: 02188526 | B1316: 4674 | C1316: 신재식 | D1316: =TEXT(A1316,"00000000") -> 02188526
